#VRML_SIM R2019a utf8
WorldInfo {
}
Viewpoint {
  orientation -0.7066726969343768 0.6792928311432044 0.1979266252047569 0.7501369123728284
  position 3.7419335142213863 4.791110584381655 6.819920081333566
}
TexturedBackground {
}
TexturedBackgroundLight {
}
Floor {
}
Solid {
  translation 0.5700000000000001 0.05 0
  children [
    Shape {
      appearance PBRAppearance {
        baseColor 0.20143434805828947 1 0.857145037003128
      }
      geometry DEF G_OBSTACLE Box {
        size 0.1 0.1 0.1
      }
    }
  ]
  boundingObject USE G_OBSTACLE
}
Robot {
  translation 0.1 0.075 0.1
  children [
    DEF GR_BODY Group {
      children [
        DEF ROBOT_BODY Shape {
          appearance PBRAppearance {
            baseColor 0.9869535362783246 0.1892576485847257 0.11616693369954986
          }
          geometry DEF G_BODY Box {
            size 0.25 0.07 0.1
          }
        }
        DEF CRAZY_WHEEL Transform {
          translation 0.11 -0.05 0
          children [
            Shape {
              appearance PBRAppearance {
                baseColor 0.05510032806897078 0 0.9981994354161898
                roughness 1
                metalness 0
              }
              geometry DEF G_CRAZYWHEEL Sphere {
                radius 0.015
              }
            }
          ]
        }
      ]
    }
    DEF WHEEL1_JOINT HingeJoint {
      jointParameters HingeJointParameters {
        axis 0 0 1
        anchor -0.05 0 0.06
      }
      device [
        PositionSensor {
          name "encoder1"
          resolution 1
        }
        RotationalMotor {
          name "motor_right"
          maxVelocity 8.3331
          maxTorque 0.4903
        }
      ]
      endPoint DEF WHEEL1 Solid {
        translation -0.05 0 0.06
        rotation -1 0 0 1.570799693899574
        children [
          DEF SH_WHEEL Shape {
            appearance DEF C_WHEEL PBRAppearance {
              baseColor 0 0 0
              roughness 1
              metalness 0
            }
            geometry DEF G_WHEEL Cylinder {
              height 0.02
              radius 0.075
            }
          }
        ]
        boundingObject USE G_WHEEL
        physics Physics {
        }
      }
    }
    DEF WHEEL2_JOINT HingeJoint {
      jointParameters HingeJointParameters {
        axis 0 0 1
        anchor -0.05 0 -0.06
      }
      device [
        RotationalMotor {
          name "motor_left"
          maxVelocity 8.3331
          maxTorque 0.4903
        }
      ]
      endPoint Solid {
        translation -0.05 0 -0.06
        rotation -1 0 0 1.5708003061004252
        children [
          Shape {
            appearance USE C_WHEEL
            geometry USE G_WHEEL
          }
        ]
        name "solid(1)"
        boundingObject USE G_WHEEL
        physics Physics {
        }
      }
    }
    DistanceSensor {
      translation 0.125 0 0
      children [
        Shape {
          appearance PBRAppearance {
            baseColor 0.9976501106279088 0.876401922636759 0.09803921568627451
          }
          geometry Box {
            size 0.02 0.01 0.01
          }
        }
      ]
      name "distance_sensor"
      lookupTable [
        0 0 0
        0.02 0 0
        11 1023 0
      ]
      resolution 1
    }
  ]
  boundingObject USE GR_BODY
  physics Physics {
  }
  controller "u2_wp"
}
